Workbook

Sheet README
A1: Month-End Close & Compliance Pack
A2: Portfolio piece: Financial Accountant capability (retail environment)
A4: IMPORTANT | B4: All figures are SIMULATED and illustrative at a scale loosely comparable to a mid-sized ASX specialty retailer. They are NOT Adairs' reported results and no internal company data is used. Replace the inputs with figures from the published Annual Report / half-year results if you want the pack anchored to reported numbers.
A6: Purpose | B6: Demonstrates a full monthly close: trial balance, balance sheet reconciliations with ageing and sign-off, P&L flux analysis, a close calendar with owners and due dates, and a control sheet that proves everything ties. BAS/IAS and FBT workings are built and linked to the GL; payroll oversight, a driver-based rolling forecast with scenario switch, and a Python bank reconciliation automation are also built.
A8: Tab | B8: What it does
A9: Control | B9: One-page proof the close ties: TB balances, journals net to zero, P&L agrees to TB, all reconciliations reconciled. Overall PASS / REVIEW flag.
A10: Inputs | B10: Period, preparer, GST rate, ageing and flux thresholds. Every assumption lives here.
A11: CoA | B11: Chart of accounts with type, statement, normal balance, reconciliation owner, plus a change-control log.
A12: TB | B12: Simulated trial balance (prior month closing, closing, month movement, budget, prior year). Debits positive, credits negative.
A13: Close_Calendar | B13: Day-by-day close checklist with working-day due dates, owners, status dropdowns and completion %.
A14: Rec_Summary | B14: Dashboard of all balance sheet reconciliations: GL vs source, difference, journals required, aged items.
A15: Rec_Bank ... Rec_Payroll | B15: Eight reconciliation tabs on one standard template (GL, source balance, timing items vs GL adjustments, ageing, sign-off).
A16: Variance | B16: Month P&L actual vs budget vs prior year, favourable/(unfavourable), automatic 'Explain' flags, commentary column.
A17: BAS_IAS | B17: Monthly BAS (G1, G2, G3, G10, G11, 1A, 1B, W1, W2) built from TB data, reconciled back to GL GST and PAYG accounts with every difference explained, plus IAS workings.
... A22: Colour legend | B22: Blue = hardcoded input / simulated data
B23: Black = formula on the same sheet
B24: Green = link to another sheet
B25: Yellow fill = cell to complete (commentary, sign-off)
A27: Sign convention | B27: TB: debits positive, credits negative. Reconciliation tabs show liabilities as positive (sign factor on each tab).
A28: Reconciliation logic | B28: Difference = (GL balance + GL adjustments) - (source balance + timing items). Timing items clear on their own next period; GL adjustments need a journal. Items older than the ageing threshold are flagged.

Sheet Control
A1: Close Control Sheet
A2: Every check below must show PASS before the period is locked
A3: Period end: | C3: =Inputs!$C$5 -> 46295
A5: # | B5: Control check | C5: Value | D5: Result
A6: 1 | B6: Trial balance (closing) sums to nil | C6: =ROUND(TB!F47,0) -> 0 | D6: =IF(C6=0,"PASS","FAIL") -> PASS
A7: 2 | B7: Trial balance (prior month) sums to nil | C7: =ROUND(TB!E47,0) -> 0 | D7: =IF(C7=0,"PASS","FAIL") -> PASS
A8: 3 | B8: Month movements net to nil (journals balance) | C8: =ROUND(TB!G47,0) -> 0 | D8: =IF(C8=0,"PASS","FAIL") -> PASS
A9: 4 | B9: P&L: month NPBT per Variance agrees to TB movement | C9: =ROUND(Variance!C30+SUMIF(TB!$D$6:$D$46,"PL",TB!$G$6:$G$46),0) -> 0 | D9: =IF(C9=0,"PASS","FAIL") -> PASS
A10: 5 | B10: All balance sheet reconciliations reconciled (count not reconciled) | C10: =COUNTIF(Rec_Summary!G6:G13,"<>RECONCILED") -> 0 | D10: =IF(C10=0,"PASS","FAIL") -> PASS
A11: 6 | B11: Total unreconciled difference across reconciliations | C11: =Rec_Summary!F14 -> 0 | D11: =IF(ABS(C11)<=Inputs!$C$12,"PASS","FAIL") -> PASS
A12: 7 | B12: BAS GST and PAYG-W agree to GL after documented items (unexplained difference) | C12: =ROUND(BAS_IAS!H33,0) -> 0 | D12: =IF(C12=0,"PASS","FAIL") -> PASS
A13: 8 | B13: FBT summary agrees to schedule total (difference) | C13: =ROUND(FBT!E38,0) -> 0 | D13: =IF(C13=0,"PASS","FAIL") -> PASS
A14: 9 | B14: Fixed asset register agrees to GL, P&L depreciation and BAS capex (sum of differences) | C14: =ROUND(FA_Register!F31,0) -> 0 | D14: =IF(C14=0,"PASS","FAIL") -> PASS
A15: 10 | B15: Reconciling items older than ageing threshold (count) | C15: =Rec_Summary!I14 -> 1 | D15: =IF(C15=0,"PASS","REVIEW") -> REVIEW
A16: 11 | B16: Close calendar tasks completed | C16: =Close_Calendar!B3 -> 0.375 | D16: =IF(C16=1,"PASS","IN PROGRESS") -> IN PROGRESS
B18: Overall status (hard controls 1-9) | D18: =IF(AND(D6="PASS",D7="PASS",D8="PASS",D9="PASS",D10="PASS",D11="PASS",D12="PASS",D13="PASS",D14="PASS"),"ALL PASS","REVIEW") -> ALL PASS
B19: Checks 10-11 are workflow indicators: aged items and close progress. They do not fail the hard controls.

Sheet Inputs
A1: Inputs & Assumptions
A2: Blue cells are inputs; everything else in the workbook reads from here
B3: Entity | C3: Specialty retailer (simulated, Adairs-style) | D3: Illustrative entity; not Adairs reported data
B4: Reporting period | C4: September 2026 (Q1 FY27) | D4: Label only
B5: Period end date | C5: 46295 | D5: Drives close calendar due dates and ageing
B6: Prepared by | C6: Bhagyashree Amblimath | D6: Preparer on all reconciliations
B7: Reviewed by | C7: Financial Controller (simulated) | D7: Reviewer sign-off is left blank for completion
B8: GST rate | C8: 0.1 | D8: Australian GST rate
B9: Reconciling-item ageing threshold (days) | C9: 30 | D9: Items older than this are flagged 'Aged'
B10: Flux threshold ($) | C10: 100000 | D10: Variance must exceed this AND the % threshold to flag 'Explain'
B11: Flux threshold (%) | C11: 0.05 | D11: As above
B12: Reconciliation tolerance ($) | C12: 1 | D12: Differences under this show as RECONCILED

Sheet CoA
A1: Chart of Accounts
A2: Simulated retail chart of accounts with reconciliation ownership
A5: Code | B5: Account name | C5: Type | D5: Statement | E5: Normal bal. | F5: Reconciled in | G5: Owner
A6: 1000 | B6: Cash at bank - operating | C6: Asset | D6: BS | E6: Dr | F6: Rec_Bank | G6: Treasury
A7: 1010 | B7: Store floats and cash on hand | C7: Asset | D7: BS | E7: Dr | G7: Retail Ops
A8: 1100 | B8: Trade debtors | C8: Asset | D8: BS | E8: Dr | F8: Rec_AR | G8: AR
A9: 1150 | B9: Other receivables | C9: Asset | D9: BS | E9: Dr | G9: AR
A10: 1200 | B10: Inventory - finished goods | C10: Asset | D10: BS | E10: Dr | F10: Rec_Inventory | G10: Supply Chain Finance
A11: 1210 | B11: Inventory in transit | C11: Asset | D11: BS | E11: Dr | F11: Rec_Inventory | G11: Supply Chain Finance
A12: 1300 | B12: Prepayments | C12: Asset | D12: BS | E12: Dr | F12: Rec_Prepayments | G12: Financial Accountant
A13: 1500 | B13: Store fit-out - cost | C13: Asset | D13: BS | E13: Dr | F13: FA_Register | G13: Financial Accountant
A14: 1505 | B14: IT equipment - cost | C14: Asset | D14: BS | E14: Dr | F14: FA_Register | G14: Financial Accountant
A15: 1510 | B15: Store fit-out - accumulated depreciation | C15: Asset | D15: BS | E15: Cr | F15: FA_Register | G15: Financial Accountant
A16: 1515 | B16: IT equipment - accumulated depreciation | C16: Asset | D16: BS | E16: Cr | F16: FA_Register | G16: Financial Accountant
A17: 2000 | B17: Trade creditors | C17: Liability | D17: BS | E17: Cr | F17: Rec_AP | G17: AP
A18: 2010 | B18: Accrued expenses | C18: Liability | D18: BS | E18: Cr | F18: Rec_Accruals | G18: Financial Accountant
A19: 2020 | B19: Goods received not invoiced (GRNI) | C19: Liability | D19: BS | E19: Cr | F19: Rec_Accruals | G19: Supply Chain Finance
A20: 2100 | B20: PAYG withholding payable | C20: Liability | D20: BS | E20: Cr | F20: Rec_Payroll | G20: Payroll
A21: 2110 | B21: Superannuation payable | C21: Liability | D21: BS | E21: Cr | F21: Rec_Payroll | G21: Payroll
A22: 2120 | B22: Accrued wages | C22: Liability | D22: BS | E22: Cr | F22: Rec_Payroll | G22: Payroll
A23: 2130 | B23: Provision - annual leave | C23: Liability | D23: BS | E23: Cr | G23: Payroll
A24: 2300 | B24: GST collected | C24: Liability | D24: BS | E24: Cr | F24: Rec_GST | G24: Financial Accountant
A25: 2310 | B25: GST paid (input tax credits) | C25: Asset | D25: BS | E25: Dr | F25: Rec_GST | G25: Financial Accountant
A26: 2400 | B26: Gift card liability | C26: Liability | D26: BS | E26: Cr | G26: Retail Ops
A27: 2500 | B27: Borrowings | C27: Liability | D27: BS | E27: Cr | G27: Treasury
A28: 3000 | B28: Share capital | C28: Equity | D28: BS | E28: Cr | G28: Financial Controller
A29: 3100 | B29: Retained earnings - opening | C29: Equity | D29: BS | E29: Cr | G29: Financial Controller
A30: 4000 | B30: Sales - stores | C30: Revenue | D30: PL | E30: Cr | G30: Financial Accountant
A31: 4010 | B31: Sales - online | C31: Revenue | D31: PL | E31: Cr | G31: Financial Accountant
A32: 4900 | B32: Sales returns and discounts | C32: Revenue | D32: PL | E32: Dr | G32: Financial Accountant
A33: 5000 | B33: Cost of goods sold | C33: COGS | D33: PL | E33: Dr | G33: Supply Chain Finance
A34: 5010 | B34: Freight inwards | C34: COGS | D34: PL | E34: Dr | G34: Supply Chain Finance
A35: 5020 | B35: Inventory shrinkage and provisions | C35: COGS | D35: PL | E35: Dr | G35: Supply Chain Finance
A36: 6000 | B36: Wages and salaries - stores | C36: Expense | D36: PL | E36: Dr | G36: Payroll
A37: 6010 | B37: Wages and salaries - head office | C37: Expense | D37: PL | E37: Dr | G37: Payroll
... A46: 7000 | B46: Interest expense | C46: Expense | D46: PL | E46: Dr | G46: Treasury
A49: Chart of accounts change log (illustrative entries)
A50: Date | B50: Change | C50: Requested by | D50: Approved by
A51: 46217 | B51: Added 2020 GRNI to separate accrued inventory from general accruals | C51: Supply Chain Finance | D51: Financial Controller
A52: 46237 | B52: Split fit-out and IT equipment into separate cost / accumulated depreciation pairs | C52: Financial Accountant | D52: Financial Controller

Sheet TB
A1: Trial Balance
A2: Debits positive, credits negative. P&L closing balances are year-to-date; movement = this month's activity
A3: Period end: | B3: =Inputs!$C$5 -> 46295
A5: Code | B5: Account name | C5: Type | D5: Statement | E5: Prior month closing ($) | F5: Closing balance ($) | G5: Month movement ($) | H5: Month budget ($) | I5: Prior-year month ($)
A6: 1000 | B6: =INDEX(CoA!$B$6:$B$46,MATCH($A6,CoA!$A$6:$A$46,0)) -> Cash at bank - operating | C6: =INDEX(CoA!$C$6:$C$46,MATCH($A6,CoA!$A$6:$A$46,0)) -> Asset | D6: =INDEX(CoA!$D$6:$D$46,MATCH($A6,CoA!$A$6:$A$46,0)) -> BS | E6: 6500000 | F6: 7190000 | G6: =F6-E6 -> 690000
A7: 1010 | B7: =INDEX(CoA!$B$6:$B$46,MATCH($A7,CoA!$A$6:$A$46,0)) -> Store floats and cash on hand | C7: =INDEX(CoA!$C$6:$C$46,MATCH($A7,CoA!$A$6:$A$46,0)) -> Asset | D7: =INDEX(CoA!$D$6:$D$46,MATCH($A7,CoA!$A$6:$A$46,0)) -> BS | E7: 400000 | F7: 410000 | G7: =F7-E7 -> 10000
A8: 1100 | B8: =INDEX(CoA!$B$6:$B$46,MATCH($A8,CoA!$A$6:$A$46,0)) -> Trade debtors | C8: =INDEX(CoA!$C$6:$C$46,MATCH($A8,CoA!$A$6:$A$46,0)) -> Asset | D8: =INDEX(CoA!$D$6:$D$46,MATCH($A8,CoA!$A$6:$A$46,0)) -> BS | E8: 2980000 | F8: 3150000 | G8: =F8-E8 -> 170000
A9: 1150 | B9: =INDEX(CoA!$B$6:$B$46,MATCH($A9,CoA!$A$6:$A$46,0)) -> Other receivables | C9: =INDEX(CoA!$C$6:$C$46,MATCH($A9,CoA!$A$6:$A$46,0)) -> Asset | D9: =INDEX(CoA!$D$6:$D$46,MATCH($A9,CoA!$A$6:$A$46,0)) -> BS | E9: 590000 | F9: 640000 | G9: =F9-E9 -> 50000
A10: 1200 | B10: =INDEX(CoA!$B$6:$B$46,MATCH($A10,CoA!$A$6:$A$46,0)) -> Inventory - finished goods | C10: =INDEX(CoA!$C$6:$C$46,MATCH($A10,CoA!$A$6:$A$46,0)) -> Asset | D10: =INDEX(CoA!$D$6:$D$46,MATCH($A10,CoA!$A$6:$A$46,0)) -> BS | E10: 93200000 | F10: 96500000 | G10: =F10-E10 -> 3300000
A11: 1210 | B11: =INDEX(CoA!$B$6:$B$46,MATCH($A11,CoA!$A$6:$A$46,0)) -> Inventory in transit | C11: =INDEX(CoA!$C$6:$C$46,MATCH($A11,CoA!$A$6:$A$46,0)) -> Asset | D11: =INDEX(CoA!$D$6:$D$46,MATCH($A11,CoA!$A$6:$A$46,0)) -> BS | E11: 9100000 | F11: 8200000 | G11: =F11-E11 -> -900000
A12: 1300 | B12: =INDEX(CoA!$B$6:$B$46,MATCH($A12,CoA!$A$6:$A$46,0)) -> Prepayments | C12: =INDEX(CoA!$C$6:$C$46,MATCH($A12,CoA!$A$6:$A$46,0)) -> Asset | D12: =INDEX(CoA!$D$6:$D$46,MATCH($A12,CoA!$A$6:$A$46,0)) -> BS | E12: 5150000 | F12: 5400000 | G12: =F12-E12 -> 250000
A13: 1500 | B13: =INDEX(CoA!$B$6:$B$46,MATCH($A13,CoA!$A$6:$A$46,0)) -> Store fit-out - cost | C13: =INDEX(CoA!$C$6:$C$46,MATCH($A13,CoA!$A$6:$A$46,0)) -> Asset | D13: =INDEX(CoA!$D$6:$D$46,MATCH($A13,CoA!$A$6:$A$46,0)) -> BS | E13: 146300000 | F13: 148000000 | G13: =F13-E13 -> 1700000
A14: 1505 | B14: =INDEX(CoA!$B$6:$B$46,MATCH($A14,CoA!$A$6:$A$46,0)) -> IT equipment - cost | C14: =INDEX(CoA!$C$6:$C$46,MATCH($A14,CoA!$A$6:$A$46,0)) -> Asset | D14: =INDEX(CoA!$D$6:$D$46,MATCH($A14,CoA!$A$6:$A$46,0)) -> BS | E14: 21100000 | F14: 21500000 | G14: =F14-E14 -> 400000
A15: 1510 | B15: =INDEX(CoA!$B$6:$B$46,MATCH($A15,CoA!$A$6:$A$46,0)) -> Store fit-out - accumulated depreciation | C15: =INDEX(CoA!$C$6:$C$46,MATCH($A15,CoA!$A$6:$A$46,0)) -> Asset | D15: =INDEX(CoA!$D$6:$D$46,MATCH($A15,CoA!$A$6:$A$46,0)) -> BS | E15: -70000000 | F15: -71200000 | G15: =F15-E15 -> -1200000
A16: 1515 | B16: =INDEX(CoA!$B$6:$B$46,MATCH($A16,CoA!$A$6:$A$46,0)) -> IT equipment - accumulated depreciation | C16: =INDEX(CoA!$C$6:$C$46,MATCH($A16,CoA!$A$6:$A$46,0)) -> Asset | D16: =INDEX(CoA!$D$6:$D$46,MATCH($A16,CoA!$A$6:$A$46,0)) -> BS | E16: -12950000 | F16: -13400000 | G16: =F16-E16 -> -450000
A17: 2000 | B17: =INDEX(CoA!$B$6:$B$46,MATCH($A17,CoA!$A$6:$A$46,0)) -> Trade creditors | C17: =INDEX(CoA!$C$6:$C$46,MATCH($A17,CoA!$A$6:$A$46,0)) -> Liability | D17: =INDEX(CoA!$D$6:$D$46,MATCH($A17,CoA!$A$6:$A$46,0)) -> BS | E17: -26400000 | F17: -27800000 | G17: =F17-E17 -> -1400000
... A29: 3100 | B29: =INDEX(CoA!$B$6:$B$46,MATCH($A29,CoA!$A$6:$A$46,0)) -> Retained earnings - opening | C29: =INDEX(CoA!$C$6:$C$46,MATCH($A29,CoA!$A$6:$A$46,0)) -> Equity | D29: =INDEX(CoA!$D$6:$D$46,MATCH($A29,CoA!$A$6:$A$46,0)) -> BS | E29: -20098000 | F29: -20098000 | G29: =F29-E29 -> 0
A30: 4000 | B30: =INDEX(CoA!$B$6:$B$46,MATCH($A30,CoA!$A$6:$A$46,0)) -> Sales - stores | C30: =INDEX(CoA!$C$6:$C$46,MATCH($A30,CoA!$A$6:$A$46,0)) -> Revenue | D30: =INDEX(CoA!$D$6:$D$46,MATCH($A30,CoA!$A$6:$A$46,0)) -> PL | E30: -74108000 | F30: -112308000 | G30: =F30-E30 -> -38200000 | H30: -37600000 | I30: -35100000
A31: 4010 | B31: =INDEX(CoA!$B$6:$B$46,MATCH($A31,CoA!$A$6:$A$46,0)) -> Sales - online | C31: =INDEX(CoA!$C$6:$C$46,MATCH($A31,CoA!$A$6:$A$46,0)) -> Revenue | D31: =INDEX(CoA!$D$6:$D$46,MATCH($A31,CoA!$A$6:$A$46,0)) -> PL | E31: -26966000 | F31: -40866000 | G31: =F31-E31 -> -13900000 | H31: -14500000 | I31: -11200000
A32: 4900 | B32: =INDEX(CoA!$B$6:$B$46,MATCH($A32,CoA!$A$6:$A$46,0)) -> Sales returns and discounts | C32: =INDEX(CoA!$C$6:$C$46,MATCH($A32,CoA!$A$6:$A$46,0)) -> Revenue | D32: =INDEX(CoA!$D$6:$D$46,MATCH($A32,CoA!$A$6:$A$46,0)) -> PL | E32: 3783000 | F32: 5733000 | G32: =F32-E32 -> 1950000 | H32: 1800000 | I32: 1700000
A33: 5000 | B33: =INDEX(CoA!$B$6:$B$46,MATCH($A33,CoA!$A$6:$A$46,0)) -> Cost of goods sold | C33: =INDEX(CoA!$C$6:$C$46,MATCH($A33,CoA!$A$6:$A$46,0)) -> COGS | D33: =INDEX(CoA!$D$6:$D$46,MATCH($A33,CoA!$A$6:$A$46,0)) -> PL | E33: 38024000 | F33: 57624000 | G33: =F33-E33 -> 19600000 | H33: 19300000 | I33: 18200000
A34: 5010 | B34: =INDEX(CoA!$B$6:$B$46,MATCH($A34,CoA!$A$6:$A$46,0)) -> Freight inwards | C34: =INDEX(CoA!$C$6:$C$46,MATCH($A34,CoA!$A$6:$A$46,0)) -> COGS | D34: =INDEX(CoA!$D$6:$D$46,MATCH($A34,CoA!$A$6:$A$46,0)) -> PL | E34: 3298000 | F34: 4998000 | G34: =F34-E34 -> 1700000 | H34: 1600000 | I34: 1450000
A35: 5020 | B35: =INDEX(CoA!$B$6:$B$46,MATCH($A35,CoA!$A$6:$A$46,0)) -> Inventory shrinkage and provisions | C35: =INDEX(CoA!$C$6:$C$46,MATCH($A35,CoA!$A$6:$A$46,0)) -> COGS | D35: =INDEX(CoA!$D$6:$D$46,MATCH($A35,CoA!$A$6:$A$46,0)) -> PL | E35: 815000 | F35: 1235000 | G35: =F35-E35 -> 420000 | H35: 350000 | I35: 330000
A36: 6000 | B36: =INDEX(CoA!$B$6:$B$46,MATCH($A36,CoA!$A$6:$A$46,0)) -> Wages and salaries - stores | C36: =INDEX(CoA!$C$6:$C$46,MATCH($A36,CoA!$A$6:$A$46,0)) -> Expense | D36: =INDEX(CoA!$D$6:$D$46,MATCH($A36,CoA!$A$6:$A$46,0)) -> PL | E36: 17266000 | F36: 26166000 | G36: =F36-E36 -> 8900000 | H36: 8700000 | I36: 8100000
A37: 6010 | B37: =INDEX(CoA!$B$6:$B$46,MATCH($A37,CoA!$A$6:$A$46,0)) -> Wages and salaries - head office | C37: =INDEX(CoA!$C$6:$C$46,MATCH($A37,CoA!$A$6:$A$46,0)) -> Expense | D37: =INDEX(CoA!$D$6:$D$46,MATCH($A37,CoA!$A$6:$A$46,0)) -> PL | E37: 6014000 | F37: 9114000 | G37: =F37-E37 -> 3100000 | H37: 3050000 | I37: 2800000
A38: 6020 | B38: =INDEX(CoA!$B$6:$B$46,MATCH($A38,CoA!$A$6:$A$46,0)) -> Superannuation expense | C38: =INDEX(CoA!$C$6:$C$46,MATCH($A38,CoA!$A$6:$A$46,0)) -> Expense | D38: =INDEX(CoA!$D$6:$D$46,MATCH($A38,CoA!$A$6:$A$46,0)) -> PL | E38: 2794000 | F38: 4234000 | G38: =F38-E38 -> 1440000 | H38: 1410000 | I38: 1260000
A39: 6100 | B39: =INDEX(CoA!$B$6:$B$46,MATCH($A39,CoA!$A$6:$A$46,0)) -> Rent and occupancy | C39: =INDEX(CoA!$C$6:$C$46,MATCH($A39,CoA!$A$6:$A$46,0)) -> Expense | D39: =INDEX(CoA!$D$6:$D$46,MATCH($A39,CoA!$A$6:$A$46,0)) -> PL | E39: 8342000 | F39: 12642000 | G39: =F39-E39 -> 4300000 | H39: 4300000 | I39: 4050000
A40: 6110 | B40: =INDEX(CoA!$B$6:$B$46,MATCH($A40,CoA!$A$6:$A$46,0)) -> Marketing | C40: =INDEX(CoA!$C$6:$C$46,MATCH($A40,CoA!$A$6:$A$46,0)) -> Expense | D40: =INDEX(CoA!$D$6:$D$46,MATCH($A40,CoA!$A$6:$A$46,0)) -> PL | E40: 6499000 | F40: 9849000 | G40: =F40-E40 -> 3350000 | H40: 3000000 | I40: 2700000
A41: 6120 | B41: =INDEX(CoA!$B$6:$B$46,MATCH($A41,CoA!$A$6:$A$46,0)) -> Depreciation | C41: =INDEX(CoA!$C$6:$C$46,MATCH($A41,CoA!$A$6:$A$46,0)) -> Expense | D41: =INDEX(CoA!$D$6:$D$46,MATCH($A41,CoA!$A$6:$A$46,0)) -> PL | E41: 3201000 | F41: 4851000 | G41: =F41-E41 -> 1650000 | H41: 1600000 | I41: 1500000
... A46: 7000 | B46: =INDEX(CoA!$B$6:$B$46,MATCH($A46,CoA!$A$6:$A$46,0)) -> Interest expense | C46: =INDEX(CoA!$C$6:$C$46,MATCH($A46,CoA!$A$6:$A$46,0)) -> Expense | D46: =INDEX(CoA!$D$6:$D$46,MATCH($A46,CoA!$A$6:$A$46,0)) -> PL | E46: 1242000 | F46: 1882000 | G46: =F46-E46 -> 640000 | H46: 650000 | I46: 700000
B47: Total (must be nil) | E47: =SUM(E6:E46) -> 0 | F47: =SUM(F6:F46) -> 0 | G47: =SUM(G6:G46) -> 0
A49: Notes
A50: 1. All balances are simulated. Cash at bank (1000) closing is set so the TB balances; it is then reconciled to a simulated bank statement on Rec_Bank.
A51: 2. Retained earnings (3100) is the opening balance and is unchanged during the year; P&L accounts hold year-to-date balances.
A52: 3. Budget and prior-year columns are simulated P&L month figures (debit positive).

Sheet Close_Calendar
A1: Month-End Close Calendar
A2: Working-day due dates calculated from the period end (weekends excluded; public holidays not modelled)
A3: Completion: | B3: =COUNTIF(G6:G29,"Complete")/COUNTA(G6:G29) -> 0.375
A5: # | B5: Work day | C5: Due date | D5: Task | E5: Owner | F5: Linked tab | G5: Status | H5: Notes / evidence
A6: 1 | B6: 1 | C6: =WORKDAY(Inputs!$C$5,B6) -> 46296 | D6: Confirm AP, AR, payroll and inventory subledger cut-off | E6: AP / AR / Payroll | F6: - | G6: Complete | H6: Cut-off sign-off emailed
A7: 2 | B7: 1 | C7: =WORKDAY(Inputs!$C$5,B7) -> 46296 | D7: Post daily store sales, card settlement and gift card journals | E7: Treasury | F7: Rec_Bank | G7: Complete
A8: 3 | B8: 1 | C8: =WORKDAY(Inputs!$C$5,B8) -> 46296 | D8: Run and post depreciation for all asset classes | E8: Financial Accountant | F8: FA_Register | G8: Complete | H8: Ties to fixed asset roll-forward
A9: 4 | B9: 2 | C9: =WORKDAY(Inputs!$C$5,B9) -> 46297 | D9: Post payroll journals (wages, PAYG, super) and leave provision movement | E9: Payroll | F9: Rec_Payroll | G9: Complete
A10: 5 | B10: 2 | C10: =WORKDAY(Inputs!$C$5,B10) -> 46297 | D10: Post accruals, GRNI and recurring journals | E10: Financial Accountant | F10: Rec_Accruals | G10: Complete
A11: 6 | B11: 2 | C11: =WORKDAY(Inputs!$C$5,B11) -> 46297 | D11: Post prepayment amortisation | E11: Financial Accountant | F11: Rec_Prepayments | G11: Complete
A12: 7 | B12: 2 | C12: =WORKDAY(Inputs!$C$5,B12) -> 46297 | D12: Bank reconciliation prepared | E12: Treasury | F12: Rec_Bank | G12: Complete
A13: 8 | B13: 3 | C13: =WORKDAY(Inputs!$C$5,B13) -> 46300 | D13: AP subledger to GL reconciliation | E13: AP | F13: Rec_AP | G13: Complete
A14: 9 | B14: 3 | C14: =WORKDAY(Inputs!$C$5,B14) -> 46300 | D14: AR subledger to GL reconciliation | E14: AR | F14: Rec_AR | G14: Complete
A15: 10 | B15: 3 | C15: =WORKDAY(Inputs!$C$5,B15) -> 46300 | D15: Inventory valuation to GL reconciliation; cycle count adjustments | E15: Supply Chain Finance | F15: Rec_Inventory | G15: In progress | H15: Cycle count adjustment pending
A16: 11 | B16: 3 | C16: =WORKDAY(Inputs!$C$5,B16) -> 46300 | D16: Intercompany / other receivables review | E16: AR | F16: - | G16: In progress
A17: 12 | B17: 4 | C17: =WORKDAY(Inputs!$C$5,B17) -> 46301 | D17: GST clearing reconciliation and BAS data extract | E17: Financial Accountant | F17: Rec_GST | G17: In progress
A18: 13 | B18: 4 | C18: =WORKDAY(Inputs!$C$5,B18) -> 46301 | D18: Payroll liabilities reconciliation | E18: Payroll | F18: Rec_Payroll | G18: In progress
A19: 14 | B19: 4 | C19: =WORKDAY(Inputs!$C$5,B19) -> 46301 | D19: Accruals and prepayments reconciliations | E19: Financial Accountant | F19: Rec_Accruals | G19: In progress
A20: 15 | B20: 4 | C20: =WORKDAY(Inputs!$C$5,B20) -> 46301 | D20: Post journals identified in reconciliations | E20: Financial Accountant | F20: Rec_Summary | G20: Not started
A21: 16 | B21: 5 | C21: =WORKDAY(Inputs!$C$5,B21) -> 46302 | D21: Re-run TB; confirm all control checks pass | E21: Financial Accountant | F21: Control | G21: Not started
A22: 17 | B22: 5 | C22: =WORKDAY(Inputs!$C$5,B22) -> 46302 | D22: P&L flux analysis vs budget and prior year; draft commentary | E22: Financial Accountant | F22: Variance | G22: Not started
A23: 18 | B23: 5 | C23: =WORKDAY(Inputs!$C$5,B23) -> 46302 | D23: Fixed asset register roll-forward agrees to GL | E23: Financial Accountant | F23: FA_Register | G23: Not started
A24: 19 | B24: 6 | C24: =WORKDAY(Inputs!$C$5,B24) -> 46303 | D24: Reconciliation review by Financial Controller | E24: Financial Controller | F24: Rec_Summary | G24: Not started
A25: 20 | B25: 6 | C25: =WORKDAY(Inputs!$C$5,B25) -> 46303 | D25: Review of variance commentary with operations and supply chain | E25: Financial Controller | F25: Variance | G25: Not started
A26: 21 | B26: 7 | C26: =WORKDAY(Inputs!$C$5,B26) -> 46304 | D26: Lock period in ERP and issue management accounts pack | E26: Financial Controller | F26: - | G26: Not started
A27: 22 | B27: 7 | C27: =WORKDAY(Inputs!$C$5,B27) -> 46304 | D27: Prepare BAS / IAS for lodgement | E27: Financial Accountant | F27: BAS_IAS | G27: Not started
... A29: 24 | B29: 8 | C29: =WORKDAY(Inputs!$C$5,B29) -> 46307 | D29: Close retrospective: log issues and automation opportunities | E29: Financial Accountant | F29: Automation | G29: Not started

Sheet Rec_Summary
A1: Balance Sheet Reconciliation Summary
A2: Links to each reconciliation tab
A3: Period end: | B3: =Inputs!$C$5 -> 46295
A5: Tab | B5: Account | C5: Balance per GL ($) | D5: Adjusted GL ($) | E5: Adjusted source ($) | F5: Difference ($) | G5: Status | H5: Journals required ($) | I5: Aged items
A6: Rec_Bank | B6: Cash at bank | C6: =Rec_Bank!D10 -> 7190000 | D6: =Rec_Bank!D12 -> 7151590 | E6: =Rec_Bank!D16 -> 7151590 | F6: =Rec_Bank!D18 -> 0 | G6: =Rec_Bank!E18 -> RECONCILED | H6: =Rec_Bank!D11 -> -38410 | I6: =Rec_Bank!D19 -> 1
A7: Rec_AR | B7: Trade debtors | C7: =Rec_AR!D10 -> 3150000 | D7: =Rec_AR!D12 -> 3137400 | E7: =Rec_AR!D16 -> 3137400 | F7: =Rec_AR!D18 -> 0 | G7: =Rec_AR!E18 -> RECONCILED | H7: =Rec_AR!D11 -> -12600 | I7: =Rec_AR!D19 -> 0
A8: Rec_AP | B8: Trade creditors | C8: =Rec_AP!D10 -> 27800000 | D8: =Rec_AP!D12 -> 27831280 | E8: =Rec_AP!D16 -> 27831280 | F8: =Rec_AP!D18 -> 0 | G8: =Rec_AP!E18 -> RECONCILED | H8: =Rec_AP!D11 -> 31280 | I8: =Rec_AP!D19 -> 0
A9: Rec_Inventory | B9: Inventory (finished goods and in transit) | C9: =Rec_Inventory!D10 -> 104700000 | D9: =Rec_Inventory!D12 -> 104435000 | E9: =Rec_Inventory!D16 -> 104435000 | F9: =Rec_Inventory!D18 -> 0 | G9: =Rec_Inventory!E18 -> RECONCILED | H9: =Rec_Inventory!D11 -> -265000 | I9: =Rec_Inventory!D19 -> 0
A10: Rec_Accruals | B10: Accrued expenses and GRNI | C10: =Rec_Accruals!D10 -> 11200000 | D10: =Rec_Accruals!D12 -> 10982000 | E10: =Rec_Accruals!D16 -> 10982000 | F10: =Rec_Accruals!D18 -> 0 | G10: =Rec_Accruals!E18 -> RECONCILED | H10: =Rec_Accruals!D11 -> -218000 | I10: =Rec_Accruals!D19 -> 0
A11: Rec_Prepayments | B11: Prepayments | C11: =Rec_Prepayments!D10 -> 5400000 | D11: =Rec_Prepayments!D12 -> 5358250 | E11: =Rec_Prepayments!D16 -> 5358250 | F11: =Rec_Prepayments!D18 -> 0 | G11: =Rec_Prepayments!E18 -> RECONCILED | H11: =Rec_Prepayments!D11 -> -41750 | I11: =Rec_Prepayments!D19 -> 0
A12: Rec_GST | B12: GST clearing (net GST payable) | C12: =Rec_GST!D10 -> 2665000 | D12: =Rec_GST!D12 -> 2656580 | E12: =Rec_GST!D16 -> 2656580 | F12: =Rec_GST!D18 -> 0 | G12: =Rec_GST!E18 -> RECONCILED | H12: =Rec_GST!D11 -> -8420 | I12: =Rec_GST!D19 -> 0
A13: Rec_Payroll | B13: Payroll liabilities (PAYG, super, accrued wages) | C13: =Rec_Payroll!D10 -> 4595000 | D13: =Rec_Payroll!D12 -> 4499000 | E13: =Rec_Payroll!D16 -> 4499000 | F13: =Rec_Payroll!D18 -> 0 | G13: =Rec_Payroll!E18 -> RECONCILED | H13: =Rec_Payroll!D11 -> -96000 | I13: =Rec_Payroll!D19 -> 0
B14: Total | F14: =SUM(F6:F13) -> 0 | H14: =SUM(H6:H13) -> -648900 | I14: =SUM(I6:I13) -> 1
A16: Journals required are the GL adjustments identified in reconciliation; post them before the P&L is finalised and re-run the TB.

Sheet Rec_Bank
A1: Balance Sheet Reconciliation - Cash at bank
A2: =Inputs!$C$3 -> Specialty retailer (simulated, Adairs-style)
A4: Period end | B4: =Inputs!$C$5 -> 46295
A5: GL account 1 | B5: 1000 | C5: =INDEX(CoA!$B$6:$B$46,MATCH($B5,CoA!$A$6:$A$46,0)) -> Cash at bank - operating
A6: GL account 2
A7: GL account 3
A8: Sign factor (1 = debit balance; -1 = credit balance shown positive) | B8: 1
A10: Balance per GL (TB closing) | D10: =$B$8*(IF($B$5="",0,SUMIF(TB!$A$6:$A$46,$B$5,TB!$F$6:$F$46))+IF($B$6="",0,SUMIF(TB!$A$6:$A$46,$B$6,TB!$F$6:$F$46))+IF($B$7="",0,SUMIF(TB!$A$6:$A$46,$B$7,TB!$F$6:$F$46))) -> 7190000
A11: Add / (less): GL adjustments (journals required) | D11: =SUMIF($E$22:$E$41,"GL adjustment",$D$22:$D$41) -> -38410
A12: Adjusted GL balance | D12: =D10+D11 -> 7151590
A14: Balance per source: | B14: Bank statement balance 30-Sep-2026 | D14: 6638170
A15: Add / (less): timing items (clear next period) | D15: =SUMIF($E$22:$E$41,"Timing",$D$22:$D$41) -> 513420
A16: Adjusted source balance | D16: =D14+D15 -> 7151590
A18: Unreconciled difference (adjusted GL less adjusted source) | D18: =ROUND(D12-D16,2) -> 0 | E18: =IF(ABS(D18)<=Inputs!$C$12,"RECONCILED","INVESTIGATE") -> RECONCILED
A19: Items older than ageing threshold | D19: =COUNTIF($G$22:$G$41,"Aged") -> 1
A21: Ref | B21: Description of reconciling item | C21: Item date | D21: Amount ($) | E21: Type | F21: Days open | G21: Aged? | H21: Action / owner | I21: Expected clear
A22: BNK-01 | B22: Merchant fees per bank statement not yet journalised | C22: 46295 | D22: -38410 | E22: GL adjustment | F22: =IF($C22="","",$B$4-$C22) -> 0 | G22: =IF($F22="","",IF($F22>Inputs!$C$9,"Aged","")) | H22: Journal: Dr 6150 / Cr 1000 - Treasury | I22: 46297
A23: BNK-02 | B23: Card settlement trading 30-Sep banked 1-Oct (deposit in transit) | C23: 46295 | D23: 1420350 | E23: Timing | F23: =IF($C23="","",$B$4-$C23) -> 0 | G23: =IF($F23="","",IF($F23>Inputs!$C$9,"Aged","")) | H23: Clears 1-Oct - Treasury | I23: 46296
A24: BNK-03 | B24: Supplier EFT batch released 29-Sep, cleared 1-Oct (outstanding payment) | C24: 46294 | D24: -845200 | E24: Timing | F24: =IF($C24="","",$B$4-$C24) -> 1 | G24: =IF($F24="","",IF($F24>Inputs!$C$9,"Aged","")) | H24: Clears 1-Oct - AP | I24: 46296
A25: BNK-04 | B25: Unpresented refund payments | C25: 46261 | D25: -61730 | E25: Timing | F25: =IF($C25="","",$B$4-$C25) -> 34 | G25: =IF($F25="","",IF($F25>Inputs!$C$9,"Aged","")) -> Aged | H25: Chase / reverse if stale - Treasury | I25: 46304
F26: =IF($C26="","",$B$4-$C26) | G26: =IF($F26="","",IF($F26>Inputs!$C$9,"Aged",""))
F27: =IF($C27="","",$B$4-$C27) | G27: =IF($F27="","",IF($F27>Inputs!$C$9,"Aged",""))
F28: =IF($C28="","",$B$4-$C28) | G28: =IF($F28="","",IF($F28>Inputs!$C$9,"Aged",""))
F29: =IF($C29="","",$B$4-$C29) | G29: =IF($F29="","",IF($F29>Inputs!$C$9,"Aged",""))
F30: =IF($C30="","",$B$4-$C30) | G30: =IF($F30="","",IF($F30>Inputs!$C$9,"Aged",""))
F31: =IF($C31="","",$B$4-$C31) | G31: =IF($F31="","",IF($F31>Inputs!$C$9,"Aged",""))
F32: =IF($C32="","",$B$4-$C32) | G32: =IF($F32="","",IF($F32>Inputs!$C$9,"Aged",""))
F33: =IF($C33="","",$B$4-$C33) | G33: =IF($F33="","",IF($F33>Inputs!$C$9,"Aged",""))
F34: =IF($C34="","",$B$4-$C34) | G34: =IF($F34="","",IF($F34>Inputs!$C$9,"Aged",""))
F35: =IF($C35="","",$B$4-$C35) | G35: =IF($F35="","",IF($F35>Inputs!$C$9,"Aged",""))
F36: =IF($C36="","",$B$4-$C36) | G36: =IF($F36="","",IF($F36>Inputs!$C$9,"Aged",""))
F37: =IF($C37="","",$B$4-$C37) | G37: =IF($F37="","",IF($F37>Inputs!$C$9,"Aged",""))
... F41: =IF($C41="","",$B$4-$C41) | G41: =IF($F41="","",IF($F41>Inputs!$C$9,"Aged",""))
A44: Sign-off
A45: Prepared by | B45: =Inputs!$C$6 -> Bhagyashree Amblimath | C45: 46300
A46: Reviewed by | B46: =Inputs!$C$7 -> Financial Controller (simulated) | D46: <- reviewer to date on sign-off
A48: Template notes: 'Timing' items clear on their own next period; 'GL adjustment' items need a journal. Source balance and items are simulated and hardcoded (blue); the difference must be nil.

Sheet Rec_AR
A1: Balance Sheet Reconciliation - Trade debtors
A2: =Inputs!$C$3 -> Specialty retailer (simulated, Adairs-style)
A4: Period end | B4: =Inputs!$C$5 -> 46295
A5: GL account 1 | B5: 1100 | C5: =INDEX(CoA!$B$6:$B$46,MATCH($B5,CoA!$A$6:$A$46,0)) -> Trade debtors
A6: GL account 2
A7: GL account 3
A8: Sign factor (1 = debit balance; -1 = credit balance shown positive) | B8: 1
A10: Balance per GL (TB closing) | D10: =$B$8*(IF($B$5="",0,SUMIF(TB!$A$6:$A$46,$B$5,TB!$F$6:$F$46))+IF($B$6="",0,SUMIF(TB!$A$6:$A$46,$B$6,TB!$F$6:$F$46))+IF($B$7="",0,SUMIF(TB!$A$6:$A$46,$B$7,TB!$F$6:$F$46))) -> 3150000
A11: Add / (less): GL adjustments (journals required) | D11: =SUMIF($E$22:$E$41,"GL adjustment",$D$22:$D$41) -> -12600
A12: Adjusted GL balance | D12: =D10+D11 -> 3137400
A14: Balance per source: | B14: AR subledger aged trial balance | D14: 3323800
A15: Add / (less): timing items (clear next period) | D15: =SUMIF($E$22:$E$41,"Timing",$D$22:$D$41) -> -186400
A16: Adjusted source balance | D16: =D14+D15 -> 3137400
A18: Unreconciled difference (adjusted GL less adjusted source) | D18: =ROUND(D12-D16,2) -> 0 | E18: =IF(ABS(D18)<=Inputs!$C$12,"RECONCILED","INVESTIGATE") -> RECONCILED
A19: Items older than ageing threshold | D19: =COUNTIF($G$22:$G$41,"Aged") -> 0
A21: Ref | B21: Description of reconciling item | C21: Item date | D21: Amount ($) | E21: Type | F21: Days open | G21: Aged? | H21: Action / owner | I21: Expected clear
A22: AR-01 | B22: Credit note CN-4471 in subledger; interface to GL failed | C22: 46293 | D22: -12600 | E22: GL adjustment | F22: =IF($C22="","",$B$4-$C22) -> 2 | G22: =IF($F22="","",IF($F22>Inputs!$C$9,"Aged","")) | H22: Journal: Dr 4900 / Cr 1100 - AR | I22: 46297
A23: AR-02 | B23: Customer remittance banked 30-Sep, applied in subledger 1-Oct | C23: 46295 | D23: -186400 | E23: Timing | F23: =IF($C23="","",$B$4-$C23) -> 0 | G23: =IF($F23="","",IF($F23>Inputs!$C$9,"Aged","")) | H23: Clears 1-Oct - AR | I23: 46296
F24: =IF($C24="","",$B$4-$C24) | G24: =IF($F24="","",IF($F24>Inputs!$C$9,"Aged",""))
F25: =IF($C25="","",$B$4-$C25) | G25: =IF($F25="","",IF($F25>Inputs!$C$9,"Aged",""))
F26: =IF($C26="","",$B$4-$C26) | G26: =IF($F26="","",IF($F26>Inputs!$C$9,"Aged",""))
F27: =IF($C27="","",$B$4-$C27) | G27: =IF($F27="","",IF($F27>Inputs!$C$9,"Aged",""))
F28: =IF($C28="","",$B$4-$C28) | G28: =IF($F28="","",IF($F28>Inputs!$C$9,"Aged",""))
F29: =IF($C29="","",$B$4-$C29) | G29: =IF($F29="","",IF($F29>Inputs!$C$9,"Aged",""))
F30: =IF($C30="","",$B$4-$C30) | G30: =IF($F30="","",IF($F30>Inputs!$C$9,"Aged",""))
F31: =IF($C31="","",$B$4-$C31) | G31: =IF($F31="","",IF($F31>Inputs!$C$9,"Aged",""))
F32: =IF($C32="","",$B$4-$C32) | G32: =IF($F32="","",IF($F32>Inputs!$C$9,"Aged",""))
F33: =IF($C33="","",$B$4-$C33) | G33: =IF($F33="","",IF($F33>Inputs!$C$9,"Aged",""))
F34: =IF($C34="","",$B$4-$C34) | G34: =IF($F34="","",IF($F34>Inputs!$C$9,"Aged",""))
F35: =IF($C35="","",$B$4-$C35) | G35: =IF($F35="","",IF($F35>Inputs!$C$9,"Aged",""))
... F41: =IF($C41="","",$B$4-$C41) | G41: =IF($F41="","",IF($F41>Inputs!$C$9,"Aged",""))
A44: Sign-off
A45: Prepared by | B45: =Inputs!$C$6 -> Bhagyashree Amblimath | C45: 46300
A46: Reviewed by | B46: =Inputs!$C$7 -> Financial Controller (simulated) | D46: <- reviewer to date on sign-off
A48: Template notes: 'Timing' items clear on their own next period; 'GL adjustment' items need a journal. Source balance and items are simulated and hardcoded (blue); the difference must be nil.

Sheet Rec_AP
A1: Balance Sheet Reconciliation - Trade creditors
A2: =Inputs!$C$3 -> Specialty retailer (simulated, Adairs-style)
A4: Period end | B4: =Inputs!$C$5 -> 46295
A5: GL account 1 | B5: 2000 | C5: =INDEX(CoA!$B$6:$B$46,MATCH($B5,CoA!$A$6:$A$46,0)) -> Trade creditors
A6: GL account 2
A7: GL account 3
A8: Sign factor (1 = debit balance; -1 = credit balance shown positive) | B8: -1
A10: Balance per GL (TB closing) | D10: =$B$8*(IF($B$5="",0,SUMIF(TB!$A$6:$A$46,$B$5,TB!$F$6:$F$46))+IF($B$6="",0,SUMIF(TB!$A$6:$A$46,$B$6,TB!$F$6:$F$46))+IF($B$7="",0,SUMIF(TB!$A$6:$A$46,$B$7,TB!$F$6:$F$46))) -> 27800000
A11: Add / (less): GL adjustments (journals required) | D11: =SUMIF($E$22:$E$41,"GL adjustment",$D$22:$D$41) -> 31280
A12: Adjusted GL balance | D12: =D10+D11 -> 27831280
A14: Balance per source: | B14: AP subledger creditor listing | D14: 27886180
A15: Add / (less): timing items (clear next period) | D15: =SUMIF($E$22:$E$41,"Timing",$D$22:$D$41) -> -54900
A16: Adjusted source balance | D16: =D14+D15 -> 27831280
A18: Unreconciled difference (adjusted GL less adjusted source) | D18: =ROUND(D12-D16,2) -> 0 | E18: =IF(ABS(D18)<=Inputs!$C$12,"RECONCILED","INVESTIGATE") -> RECONCILED
A19: Items older than ageing threshold | D19: =COUNTIF($G$22:$G$41,"Aged") -> 0
A21: Ref | B21: Description of reconciling item | C21: Item date | D21: Amount ($) | E21: Type | F21: Days open | G21: Aged? | H21: Action / owner | I21: Expected clear
A22: AP-01 | B22: Invoice INV-88231 in AP subledger; GL interface error | C22: 46294 | D22: 31280 | E22: GL adjustment | F22: =IF($C22="","",$B$4-$C22) -> 1 | G22: =IF($F22="","",IF($F22>Inputs!$C$9,"Aged","")) | H22: Re-run interface / manual journal - AP | I22: 46297
A23: AP-02 | B23: Supplier debit note recorded in GL 30-Sep, subledger 1-Oct | C23: 46295 | D23: -54900 | E23: Timing | F23: =IF($C23="","",$B$4-$C23) -> 0 | G23: =IF($F23="","",IF($F23>Inputs!$C$9,"Aged","")) | H23: Clears 1-Oct - AP | I23: 46296
F24: =IF($C24="","",$B$4-$C24) | G24: =IF($F24="","",IF($F24>Inputs!$C$9,"Aged",""))
F25: =IF($C25="","",$B$4-$C25) | G25: =IF($F25="","",IF($F25>Inputs!$C$9,"Aged",""))
F26: =IF($C26="","",$B$4-$C26) | G26: =IF($F26="","",IF($F26>Inputs!$C$9,"Aged",""))
F27: =IF($C27="","",$B$4-$C27) | G27: =IF($F27="","",IF($F27>Inputs!$C$9,"Aged",""))
F28: =IF($C28="","",$B$4-$C28) | G28: =IF($F28="","",IF($F28>Inputs!$C$9,"Aged",""))
F29: =IF($C29="","",$B$4-$C29) | G29: =IF($F29="","",IF($F29>Inputs!$C$9,"Aged",""))
F30: =IF($C30="","",$B$4-$C30) | G30: =IF($F30="","",IF($F30>Inputs!$C$9,"Aged",""))
F31: =IF($C31="","",$B$4-$C31) | G31: =IF($F31="","",IF($F31>Inputs!$C$9,"Aged",""))
F32: =IF($C32="","",$B$4-$C32) | G32: =IF($F32="","",IF($F32>Inputs!$C$9,"Aged",""))
F33: =IF($C33="","",$B$4-$C33) | G33: =IF($F33="","",IF($F33>Inputs!$C$9,"Aged",""))
F34: =IF($C34="","",$B$4-$C34) | G34: =IF($F34="","",IF($F34>Inputs!$C$9,"Aged",""))
F35: =IF($C35="","",$B$4-$C35) | G35: =IF($F35="","",IF($F35>Inputs!$C$9,"Aged",""))
... F41: =IF($C41="","",$B$4-$C41) | G41: =IF($F41="","",IF($F41>Inputs!$C$9,"Aged",""))
A44: Sign-off
A45: Prepared by | B45: =Inputs!$C$6 -> Bhagyashree Amblimath | C45: 46300
A46: Reviewed by | B46: =Inputs!$C$7 -> Financial Controller (simulated) | D46: <- reviewer to date on sign-off
A48: Template notes: 'Timing' items clear on their own next period; 'GL adjustment' items need a journal. Source balance and items are simulated and hardcoded (blue); the difference must be nil.

Sheet Rec_Inventory
A1: Balance Sheet Reconciliation - Inventory (finished goods and in transit)
A2: =Inputs!$C$3 -> Specialty retailer (simulated, Adairs-style)
A4: Period end | B4: =Inputs!$C$5 -> 46295
A5: GL account 1 | B5: 1200 | C5: =INDEX(CoA!$B$6:$B$46,MATCH($B5,CoA!$A$6:$A$46,0)) -> Inventory - finished goods
A6: GL account 2 | B6: 1210 | C6: =INDEX(CoA!$B$6:$B$46,MATCH($B6,CoA!$A$6:$A$46,0)) -> Inventory in transit
A7: GL account 3
A8: Sign factor (1 = debit balance; -1 = credit balance shown positive) | B8: 1
A10: Balance per GL (TB closing) | D10: =$B$8*(IF($B$5="",0,SUMIF(TB!$A$6:$A$46,$B$5,TB!$F$6:$F$46))+IF($B$6="",0,SUMIF(TB!$A$6:$A$46,$B$6,TB!$F$6:$F$46))+IF($B$7="",0,SUMIF(TB!$A$6:$A$46,$B$7,TB!$F$6:$F$46))) -> 104700000
A11: Add / (less): GL adjustments (journals required) | D11: =SUMIF($E$22:$E$41,"GL adjustment",$D$22:$D$41) -> -265000
A12: Adjusted GL balance | D12: =D10+D11 -> 104435000
A14: Balance per source: | B14: WMS valuation plus shipping report | D14: 104124500
A15: Add / (less): timing items (clear next period) | D15: =SUMIF($E$22:$E$41,"Timing",$D$22:$D$41) -> 310500
A16: Adjusted source balance | D16: =D14+D15 -> 104435000
A18: Unreconciled difference (adjusted GL less adjusted source) | D18: =ROUND(D12-D16,2) -> 0 | E18: =IF(ABS(D18)<=Inputs!$C$12,"RECONCILED","INVESTIGATE") -> RECONCILED
A19: Items older than ageing threshold | D19: =COUNTIF($G$22:$G$41,"Aged") -> 0
A21: Ref | B21: Description of reconciling item | C21: Item date | D21: Amount ($) | E21: Type | F21: Days open | G21: Aged? | H21: Action / owner | I21: Expected clear
A22: INV-01 | B22: Q1 cycle count variance; stock adjustment not yet posted | C22: 46291 | D22: -265000 | E22: GL adjustment | F22: =IF($C22="","",$B$4-$C22) -> 4 | G22: =IF($F22="","",IF($F22>Inputs!$C$9,"Aged","")) | H22: Journal: Dr 5020 / Cr 1200 - Supply Chain Finance | I22: 46298
A23: INV-02 | B23: Receipts in GL 30-Sep, booked in WMS 1-Oct | C23: 46295 | D23: 310500 | E23: Timing | F23: =IF($C23="","",$B$4-$C23) -> 0 | G23: =IF($F23="","",IF($F23>Inputs!$C$9,"Aged","")) | H23: Clears 1-Oct - Supply Chain | I23: 46296
F24: =IF($C24="","",$B$4-$C24) | G24: =IF($F24="","",IF($F24>Inputs!$C$9,"Aged",""))
F25: =IF($C25="","",$B$4-$C25) | G25: =IF($F25="","",IF($F25>Inputs!$C$9,"Aged",""))
F26: =IF($C26="","",$B$4-$C26) | G26: =IF($F26="","",IF($F26>Inputs!$C$9,"Aged",""))
F27: =IF($C27="","",$B$4-$C27) | G27: =IF($F27="","",IF($F27>Inputs!$C$9,"Aged",""))
F28: =IF($C28="","",$B$4-$C28) | G28: =IF($F28="","",IF($F28>Inputs!$C$9,"Aged",""))
F29: =IF($C29="","",$B$4-$C29) | G29: =IF($F29="","",IF($F29>Inputs!$C$9,"Aged",""))
F30: =IF($C30="","",$B$4-$C30) | G30: =IF($F30="","",IF($F30>Inputs!$C$9,"Aged",""))
F31: =IF($C31="","",$B$4-$C31) | G31: =IF($F31="","",IF($F31>Inputs!$C$9,"Aged",""))
F32: =IF($C32="","",$B$4-$C32) | G32: =IF($F32="","",IF($F32>Inputs!$C$9,"Aged",""))
F33: =IF($C33="","",$B$4-$C33) | G33: =IF($F33="","",IF($F33>Inputs!$C$9,"Aged",""))
F34: =IF($C34="","",$B$4-$C34) | G34: =IF($F34="","",IF($F34>Inputs!$C$9,"Aged",""))
F35: =IF($C35="","",$B$4-$C35) | G35: =IF($F35="","",IF($F35>Inputs!$C$9,"Aged",""))
... F41: =IF($C41="","",$B$4-$C41) | G41: =IF($F41="","",IF($F41>Inputs!$C$9,"Aged",""))
A44: Sign-off
A45: Prepared by | B45: =Inputs!$C$6 -> Bhagyashree Amblimath | C45: 46300
A46: Reviewed by | B46: =Inputs!$C$7 -> Financial Controller (simulated) | D46: <- reviewer to date on sign-off
A48: Template notes: 'Timing' items clear on their own next period; 'GL adjustment' items need a journal. Source balance and items are simulated and hardcoded (blue); the difference must be nil.

Sheet Rec_Accruals
A1: Balance Sheet Reconciliation - Accrued expenses and GRNI
A2: =Inputs!$C$3 -> Specialty retailer (simulated, Adairs-style)
A4: Period end | B4: =Inputs!$C$5 -> 46295
A5: GL account 1 | B5: 2010 | C5: =INDEX(CoA!$B$6:$B$46,MATCH($B5,CoA!$A$6:$A$46,0)) -> Accrued expenses
A6: GL account 2 | B6: 2020 | C6: =INDEX(CoA!$B$6:$B$46,MATCH($B6,CoA!$A$6:$A$46,0)) -> Goods received not invoiced (GRNI)
A7: GL account 3
A8: Sign factor (1 = debit balance; -1 = credit balance shown positive) | B8: -1
A10: Balance per GL (TB closing) | D10: =$B$8*(IF($B$5="",0,SUMIF(TB!$A$6:$A$46,$B$5,TB!$F$6:$F$46))+IF($B$6="",0,SUMIF(TB!$A$6:$A$46,$B$6,TB!$F$6:$F$46))+IF($B$7="",0,SUMIF(TB!$A$6:$A$46,$B$7,TB!$F$6:$F$46))) -> 11200000
A11: Add / (less): GL adjustments (journals required) | D11: =SUMIF($E$22:$E$41,"GL adjustment",$D$22:$D$41) -> -218000
A12: Adjusted GL balance | D12: =D10+D11 -> 10982000
A14: Balance per source: | B14: Accruals and GRNI schedule | D14: 10887000
A15: Add / (less): timing items (clear next period) | D15: =SUMIF($E$22:$E$41,"Timing",$D$22:$D$41) -> 95000
A16: Adjusted source balance | D16: =D14+D15 -> 10982000
A18: Unreconciled difference (adjusted GL less adjusted source) | D18: =ROUND(D12-D16,2) -> 0 | E18: =IF(ABS(D18)<=Inputs!$C$12,"RECONCILED","INVESTIGATE") -> RECONCILED
A19: Items older than ageing threshold | D19: =COUNTIF($G$22:$G$41,"Aged") -> 0
A21: Ref | B21: Description of reconciling item | C21: Item date | D21: Amount ($) | E21: Type | F21: Days open | G21: Aged? | H21: Action / owner | I21: Expected clear
A22: ACC-01 | B22: Rent accrual reversal not posted for September | C22: 46295 | D22: -218000 | E22: GL adjustment | F22: =IF($C22="","",$B$4-$C22) -> 0 | G22: =IF($F22="","",IF($F22>Inputs!$C$9,"Aged","")) | H22: Journal: Dr 2010 / Cr 6100 - Financial Accountant | I22: 46297
A23: ACC-02 | B23: Accrual raised 30-Sep after schedule cut-off | C23: 46295 | D23: 95000 | E23: Timing | F23: =IF($C23="","",$B$4-$C23) -> 0 | G23: =IF($F23="","",IF($F23>Inputs!$C$9,"Aged","")) | H23: Added to schedule 1-Oct | I23: 46296
F24: =IF($C24="","",$B$4-$C24) | G24: =IF($F24="","",IF($F24>Inputs!$C$9,"Aged",""))
F25: =IF($C25="","",$B$4-$C25) | G25: =IF($F25="","",IF($F25>Inputs!$C$9,"Aged",""))
F26: =IF($C26="","",$B$4-$C26) | G26: =IF($F26="","",IF($F26>Inputs!$C$9,"Aged",""))
F27: =IF($C27="","",$B$4-$C27) | G27: =IF($F27="","",IF($F27>Inputs!$C$9,"Aged",""))
F28: =IF($C28="","",$B$4-$C28) | G28: =IF($F28="","",IF($F28>Inputs!$C$9,"Aged",""))
F29: =IF($C29="","",$B$4-$C29) | G29: =IF($F29="","",IF($F29>Inputs!$C$9,"Aged",""))
F30: =IF($C30="","",$B$4-$C30) | G30: =IF($F30="","",IF($F30>Inputs!$C$9,"Aged",""))
F31: =IF($C31="","",$B$4-$C31) | G31: =IF($F31="","",IF($F31>Inputs!$C$9,"Aged",""))
F32: =IF($C32="","",$B$4-$C32) | G32: =IF($F32="","",IF($F32>Inputs!$C$9,"Aged",""))
F33: =IF($C33="","",$B$4-$C33) | G33: =IF($F33="","",IF($F33>Inputs!$C$9,"Aged",""))
F34: =IF($C34="","",$B$4-$C34) | G34: =IF($F34="","",IF($F34>Inputs!$C$9,"Aged",""))
F35: =IF($C35="","",$B$4-$C35) | G35: =IF($F35="","",IF($F35>Inputs!$C$9,"Aged",""))
... F41: =IF($C41="","",$B$4-$C41) | G41: =IF($F41="","",IF($F41>Inputs!$C$9,"Aged",""))
A44: Sign-off
A45: Prepared by | B45: =Inputs!$C$6 -> Bhagyashree Amblimath | C45: 46300
A46: Reviewed by | B46: =Inputs!$C$7 -> Financial Controller (simulated) | D46: <- reviewer to date on sign-off
A48: Template notes: 'Timing' items clear on their own next period; 'GL adjustment' items need a journal. Source balance and items are simulated and hardcoded (blue); the difference must be nil.

Sheet Rec_Prepayments
A1: Balance Sheet Reconciliation - Prepayments
A2: =Inputs!$C$3 -> Specialty retailer (simulated, Adairs-style)
A4: Period end | B4: =Inputs!$C$5 -> 46295
A5: GL account 1 | B5: 1300 | C5: =INDEX(CoA!$B$6:$B$46,MATCH($B5,CoA!$A$6:$A$46,0)) -> Prepayments
A6: GL account 2
A7: GL account 3
A8: Sign factor (1 = debit balance; -1 = credit balance shown positive) | B8: 1
A10: Balance per GL (TB closing) | D10: =$B$8*(IF($B$5="",0,SUMIF(TB!$A$6:$A$46,$B$5,TB!$F$6:$F$46))+IF($B$6="",0,SUMIF(TB!$A$6:$A$46,$B$6,TB!$F$6:$F$46))+IF($B$7="",0,SUMIF(TB!$A$6:$A$46,$B$7,TB!$F$6:$F$46))) -> 5400000
A11: Add / (less): GL adjustments (journals required) | D11: =SUMIF($E$22:$E$41,"GL adjustment",$D$22:$D$41) -> -41750
A12: Adjusted GL balance | D12: =D10+D11 -> 5358250
A14: Balance per source: | B14: Prepayment amortisation schedule | D14: 5238250
A15: Add / (less): timing items (clear next period) | D15: =SUMIF($E$22:$E$41,"Timing",$D$22:$D$41) -> 120000
A16: Adjusted source balance | D16: =D14+D15 -> 5358250
A18: Unreconciled difference (adjusted GL less adjusted source) | D18: =ROUND(D12-D16,2) -> 0 | E18: =IF(ABS(D18)<=Inputs!$C$12,"RECONCILED","INVESTIGATE") -> RECONCILED
A19: Items older than ageing threshold | D19: =COUNTIF($G$22:$G$41,"Aged") -> 0
A21: Ref | B21: Description of reconciling item | C21: Item date | D21: Amount ($) | E21: Type | F21: Days open | G21: Aged? | H21: Action / owner | I21: Expected clear
A22: PRE-01 | B22: September insurance amortisation not booked | C22: 46295 | D22: -41750 | E22: GL adjustment | F22: =IF($C22="","",$B$4-$C22) -> 0 | G22: =IF($F22="","",IF($F22>Inputs!$C$9,"Aged","")) | H22: Journal: Dr 6160 / Cr 1300 - Financial Accountant | I22: 46297
A23: PRE-02 | B23: Licence prepayment added to schedule 1-Oct, in GL 30-Sep | C23: 46295 | D23: 120000 | E23: Timing | F23: =IF($C23="","",$B$4-$C23) -> 0 | G23: =IF($F23="","",IF($F23>Inputs!$C$9,"Aged","")) | H23: Clears 1-Oct | I23: 46296
F24: =IF($C24="","",$B$4-$C24) | G24: =IF($F24="","",IF($F24>Inputs!$C$9,"Aged",""))
F25: =IF($C25="","",$B$4-$C25) | G25: =IF($F25="","",IF($F25>Inputs!$C$9,"Aged",""))
F26: =IF($C26="","",$B$4-$C26) | G26: =IF($F26="","",IF($F26>Inputs!$C$9,"Aged",""))
F27: =IF($C27="","",$B$4-$C27) | G27: =IF($F27="","",IF($F27>Inputs!$C$9,"Aged",""))
F28: =IF($C28="","",$B$4-$C28) | G28: =IF($F28="","",IF($F28>Inputs!$C$9,"Aged",""))
F29: =IF($C29="","",$B$4-$C29) | G29: =IF($F29="","",IF($F29>Inputs!$C$9,"Aged",""))
F30: =IF($C30="","",$B$4-$C30) | G30: =IF($F30="","",IF($F30>Inputs!$C$9,"Aged",""))
F31: =IF($C31="","",$B$4-$C31) | G31: =IF($F31="","",IF($F31>Inputs!$C$9,"Aged",""))
F32: =IF($C32="","",$B$4-$C32) | G32: =IF($F32="","",IF($F32>Inputs!$C$9,"Aged",""))
F33: =IF($C33="","",$B$4-$C33) | G33: =IF($F33="","",IF($F33>Inputs!$C$9,"Aged",""))
F34: =IF($C34="","",$B$4-$C34) | G34: =IF($F34="","",IF($F34>Inputs!$C$9,"Aged",""))
F35: =IF($C35="","",$B$4-$C35) | G35: =IF($F35="","",IF($F35>Inputs!$C$9,"Aged",""))
... F41: =IF($C41="","",$B$4-$C41) | G41: =IF($F41="","",IF($F41>Inputs!$C$9,"Aged",""))
A44: Sign-off
A45: Prepared by | B45: =Inputs!$C$6 -> Bhagyashree Amblimath | C45: 46300
A46: Reviewed by | B46: =Inputs!$C$7 -> Financial Controller (simulated) | D46: <- reviewer to date on sign-off
A48: Template notes: 'Timing' items clear on their own next period; 'GL adjustment' items need a journal. Source balance and items are simulated and hardcoded (blue); the difference must be nil.

Sheet Rec_GST
A1: Balance Sheet Reconciliation - GST clearing (net GST payable)
A2: =Inputs!$C$3 -> Specialty retailer (simulated, Adairs-style)
A4: Period end | B4: =Inputs!$C$5 -> 46295
A5: GL account 1 | B5: 2300 | C5: =INDEX(CoA!$B$6:$B$46,MATCH($B5,CoA!$A$6:$A$46,0)) -> GST collected
A6: GL account 2 | B6: 2310 | C6: =INDEX(CoA!$B$6:$B$46,MATCH($B6,CoA!$A$6:$A$46,0)) -> GST paid (input tax credits)
A7: GL account 3
A8: Sign factor (1 = debit balance; -1 = credit balance shown positive) | B8: -1
A10: Balance per GL (TB closing) | D10: =$B$8*(IF($B$5="",0,SUMIF(TB!$A$6:$A$46,$B$5,TB!$F$6:$F$46))+IF($B$6="",0,SUMIF(TB!$A$6:$A$46,$B$6,TB!$F$6:$F$46))+IF($B$7="",0,SUMIF(TB!$A$6:$A$46,$B$7,TB!$F$6:$F$46))) -> 2665000
A11: Add / (less): GL adjustments (journals required) | D11: =SUMIF($E$22:$E$41,"GL adjustment",$D$22:$D$41) -> -8420
A12: Adjusted GL balance | D12: =D10+D11 -> 2656580
A14: Balance per source: | B14: BAS_IAS tab: net GST payable (1A less 1B) | D14: =BAS_IAS!D23 -> 2642280
A15: Add / (less): timing items (clear next period) | D15: =SUMIF($E$22:$E$41,"Timing",$D$22:$D$41) -> 14300
A16: Adjusted source balance | D16: =D14+D15 -> 2656580
A18: Unreconciled difference (adjusted GL less adjusted source) | D18: =ROUND(D12-D16,2) -> 0 | E18: =IF(ABS(D18)<=Inputs!$C$12,"RECONCILED","INVESTIGATE") -> RECONCILED
A19: Items older than ageing threshold | D19: =COUNTIF($G$22:$G$41,"Aged") -> 0
A21: Ref | B21: Description of reconciling item | C21: Item date | D21: Amount ($) | E21: Type | F21: Days open | G21: Aged? | H21: Action / owner | I21: Expected clear
A22: GST-01 | B22: GST on petty cash and card purchases not coded in GL | C22: 46295 | D22: -8420 | E22: GL adjustment | F22: =IF($C22="","",$B$4-$C22) -> 0 | G22: =IF($F22="","",IF($F22>Inputs!$C$9,"Aged","")) | H22: Journal: Dr 2310 / Cr 6160 - Financial Accountant | I22: 46297
A23: GST-02 | B23: Online sales cut-off difference between POS and GL | C23: 46295 | D23: 14300 | E23: Timing | F23: =IF($C23="","",$B$4-$C23) -> 0 | G23: =IF($F23="","",IF($F23>Inputs!$C$9,"Aged","")) | H23: Confirm in BAS review | I23: 46300
F24: =IF($C24="","",$B$4-$C24) | G24: =IF($F24="","",IF($F24>Inputs!$C$9,"Aged",""))
F25: =IF($C25="","",$B$4-$C25) | G25: =IF($F25="","",IF($F25>Inputs!$C$9,"Aged",""))
F26: =IF($C26="","",$B$4-$C26) | G26: =IF($F26="","",IF($F26>Inputs!$C$9,"Aged",""))
F27: =IF($C27="","",$B$4-$C27) | G27: =IF($F27="","",IF($F27>Inputs!$C$9,"Aged",""))
F28: =IF($C28="","",$B$4-$C28) | G28: =IF($F28="","",IF($F28>Inputs!$C$9,"Aged",""))
F29: =IF($C29="","",$B$4-$C29) | G29: =IF($F29="","",IF($F29>Inputs!$C$9,"Aged",""))
F30: =IF($C30="","",$B$4-$C30) | G30: =IF($F30="","",IF($F30>Inputs!$C$9,"Aged",""))
F31: =IF($C31="","",$B$4-$C31) | G31: =IF($F31="","",IF($F31>Inputs!$C$9,"Aged",""))
F32: =IF($C32="","",$B$4-$C32) | G32: =IF($F32="","",IF($F32>Inputs!$C$9,"Aged",""))
F33: =IF($C33="","",$B$4-$C33) | G33: =IF($F33="","",IF($F33>Inputs!$C$9,"Aged",""))
F34: =IF($C34="","",$B$4-$C34) | G34: =IF($F34="","",IF($F34>Inputs!$C$9,"Aged",""))
F35: =IF($C35="","",$B$4-$C35) | G35: =IF($F35="","",IF($F35>Inputs!$C$9,"Aged",""))
... F41: =IF($C41="","",$B$4-$C41) | G41: =IF($F41="","",IF($F41>Inputs!$C$9,"Aged",""))
A44: Sign-off
A45: Prepared by | B45: =Inputs!$C$6 -> Bhagyashree Amblimath | C45: 46300
A46: Reviewed by | B46: =Inputs!$C$7 -> Financial Controller (simulated) | D46: <- reviewer to date on sign-off
A48: Template notes: 'Timing' items clear on their own next period; 'GL adjustment' items need a journal. Source balance and items are simulated and hardcoded (blue); the difference must be nil.

Sheet Rec_Payroll
A1: Balance Sheet Reconciliation - Payroll liabilities (PAYG, super, accrued wages)
A2: =Inputs!$C$3 -> Specialty retailer (simulated, Adairs-style)
A4: Period end | B4: =Inputs!$C$5 -> 46295
A5: GL account 1 | B5: 2100 | C5: =INDEX(CoA!$B$6:$B$46,MATCH($B5,CoA!$A$6:$A$46,0)) -> PAYG withholding payable
A6: GL account 2 | B6: 2110 | C6: =INDEX(CoA!$B$6:$B$46,MATCH($B6,CoA!$A$6:$A$46,0)) -> Superannuation payable
A7: GL account 3 | B7: 2120 | C7: =INDEX(CoA!$B$6:$B$46,MATCH($B7,CoA!$A$6:$A$46,0)) -> Accrued wages
A8: Sign factor (1 = debit balance; -1 = credit balance shown positive) | B8: -1
A10: Balance per GL (TB closing) | D10: =$B$8*(IF($B$5="",0,SUMIF(TB!$A$6:$A$46,$B$5,TB!$F$6:$F$46))+IF($B$6="",0,SUMIF(TB!$A$6:$A$46,$B$6,TB!$F$6:$F$46))+IF($B$7="",0,SUMIF(TB!$A$6:$A$46,$B$7,TB!$F$6:$F$46))) -> 4595000
A11: Add / (less): GL adjustments (journals required) | D11: =SUMIF($E$22:$E$41,"GL adjustment",$D$22:$D$41) -> -96000
A12: Adjusted GL balance | D12: =D10+D11 -> 4499000
A14: Balance per source: | B14: Payroll system liabilities report | D14: 4454000
A15: Add / (less): timing items (clear next period) | D15: =SUMIF($E$22:$E$41,"Timing",$D$22:$D$41) -> 45000
A16: Adjusted source balance | D16: =D14+D15 -> 4499000
A18: Unreconciled difference (adjusted GL less adjusted source) | D18: =ROUND(D12-D16,2) -> 0 | E18: =IF(ABS(D18)<=Inputs!$C$12,"RECONCILED","INVESTIGATE") -> RECONCILED
A19: Items older than ageing threshold | D19: =COUNTIF($G$22:$G$41,"Aged") -> 0
A21: Ref | B21: Description of reconciling item | C21: Item date | D21: Amount ($) | E21: Type | F21: Days open | G21: Aged? | H21: Action / owner | I21: Expected clear
A22: PAY-01 | B22: Super contributions paid 29-Sep (SuperStream) not journalised | C22: 46294 | D22: -96000 | E22: GL adjustment | F22: =IF($C22="","",$B$4-$C22) -> 1 | G22: =IF($F22="","",IF($F22>Inputs!$C$9,"Aged","")) | H22: Journal: Dr 2110 / Cr 1000 - Payroll | I22: 46297
A23: PAY-02 | B23: Termination payout calculated 30-Sep, paid 2-Oct | C23: 46295 | D23: 45000 | E23: Timing | F23: =IF($C23="","",$B$4-$C23) -> 0 | G23: =IF($F23="","",IF($F23>Inputs!$C$9,"Aged","")) | H23: Clears 2-Oct - Payroll | I23: 46297
F24: =IF($C24="","",$B$4-$C24) | G24: =IF($F24="","",IF($F24>Inputs!$C$9,"Aged",""))
F25: =IF($C25="","",$B$4-$C25) | G25: =IF($F25="","",IF($F25>Inputs!$C$9,"Aged",""))
F26: =IF($C26="","",$B$4-$C26) | G26: =IF($F26="","",IF($F26>Inputs!$C$9,"Aged",""))
F27: =IF($C27="","",$B$4-$C27) | G27: =IF($F27="","",IF($F27>Inputs!$C$9,"Aged",""))
F28: =IF($C28="","",$B$4-$C28) | G28: =IF($F28="","",IF($F28>Inputs!$C$9,"Aged",""))
F29: =IF($C29="","",$B$4-$C29) | G29: =IF($F29="","",IF($F29>Inputs!$C$9,"Aged",""))
F30: =IF($C30="","",$B$4-$C30) | G30: =IF($F30="","",IF($F30>Inputs!$C$9,"Aged",""))
F31: =IF($C31="","",$B$4-$C31) | G31: =IF($F31="","",IF($F31>Inputs!$C$9,"Aged",""))
F32: =IF($C32="","",$B$4-$C32) | G32: =IF($F32="","",IF($F32>Inputs!$C$9,"Aged",""))
F33: =IF($C33="","",$B$4-$C33) | G33: =IF($F33="","",IF($F33>Inputs!$C$9,"Aged",""))
F34: =IF($C34="","",$B$4-$C34) | G34: =IF($F34="","",IF($F34>Inputs!$C$9,"Aged",""))
F35: =IF($C35="","",$B$4-$C35) | G35: =IF($F35="","",IF($F35>Inputs!$C$9,"Aged",""))
... F41: =IF($C41="","",$B$4-$C41) | G41: =IF($F41="","",IF($F41>Inputs!$C$9,"Aged",""))
A44: Sign-off
A45: Prepared by | B45: =Inputs!$C$6 -> Bhagyashree Amblimath | C45: 46300
A46: Reviewed by | B46: =Inputs!$C$7 -> Financial Controller (simulated) | D46: <- reviewer to date on sign-off
A48: Template notes: 'Timing' items clear on their own next period; 'GL adjustment' items need a journal. Source balance and items are simulated and hardcoded (blue); the difference must be nil.

Sheet Variance
A1: P&L Flux Analysis - Month Actual vs Budget vs Prior Year
A2: Presented with revenue positive; variances shown favourable / (unfavourable)
A3: Period end: | B3: =Inputs!$C$5 -> 46295
A5: Code | B5: Line | C5: Actual ($) | D5: Budget ($) | E5: Var vs budget ($) | F5: Var % | G5: Prior year ($) | H5: Var vs PY % | I5: Flag | J5: Commentary (drivers and actions)
A6: 4000 | B6: =INDEX(CoA!$B$6:$B$46,MATCH($A6,CoA!$A$6:$A$46,0)) -> Sales - stores | C6: =-INDEX(TB!$G$6:$G$46,MATCH($A6,TB!$A$6:$A$46,0)) -> 38200000 | D6: =-INDEX(TB!$H$6:$H$46,MATCH($A6,TB!$A$6:$A$46,0)) -> 37600000 | E6: =C6-D6 -> 600000 | F6: =IF(D6=0,0,E6/ABS(D6)) -> 0.015957447 | G6: =-INDEX(TB!$I$6:$I$46,MATCH($A6,TB!$A$6:$A$46,0)) -> 35100000 | H6: =IF(G6=0,0,(C6-G6)/ABS(G6)) -> 0.088319088 | I6: =IF(AND(ABS(E6)>=Inputs!$C$10,ABS(F6)>=Inputs!$C$11),"Explain","")
A7: 4010 | B7: =INDEX(CoA!$B$6:$B$46,MATCH($A7,CoA!$A$6:$A$46,0)) -> Sales - online | C7: =-INDEX(TB!$G$6:$G$46,MATCH($A7,TB!$A$6:$A$46,0)) -> 13900000 | D7: =-INDEX(TB!$H$6:$H$46,MATCH($A7,TB!$A$6:$A$46,0)) -> 14500000 | E7: =C7-D7 -> -600000 | F7: =IF(D7=0,0,E7/ABS(D7)) -> -0.04137931 | G7: =-INDEX(TB!$I$6:$I$46,MATCH($A7,TB!$A$6:$A$46,0)) -> 11200000 | H7: =IF(G7=0,0,(C7-G7)/ABS(G7)) -> 0.24107143 | I7: =IF(AND(ABS(E7)>=Inputs!$C$10,ABS(F7)>=Inputs!$C$11),"Explain","")
A8: 4900 | B8: =INDEX(CoA!$B$6:$B$46,MATCH($A8,CoA!$A$6:$A$46,0)) -> Sales returns and discounts | C8: =-INDEX(TB!$G$6:$G$46,MATCH($A8,TB!$A$6:$A$46,0)) -> -1950000 | D8: =-INDEX(TB!$H$6:$H$46,MATCH($A8,TB!$A$6:$A$46,0)) -> -1800000 | E8: =C8-D8 -> -150000 | F8: =IF(D8=0,0,E8/ABS(D8)) -> -0.083333333 | G8: =-INDEX(TB!$I$6:$I$46,MATCH($A8,TB!$A$6:$A$46,0)) -> -1700000 | H8: =IF(G8=0,0,(C8-G8)/ABS(G8)) -> -0.14705882 | I8: =IF(AND(ABS(E8)>=Inputs!$C$10,ABS(F8)>=Inputs!$C$11),"Explain","") -> Explain | J8: DRAFT. Returns and discounts $1.95m vs $1.80m budget: 3.7% of gross sales vs 3.5% budget and 3.7% prior year, so the rate is in line with last year but above plan. Confirm promotional discount depth with Retail. Credit note CN-4471 ($12.6k, AR-01) is not yet in the GL and will add to this line.
B9: Net sales | C9: =SUM(C6:C8) -> 50150000 | D9: =SUM(D6:D8) -> 50300000 | E9: =C9-D9 -> -150000 | F9: =IF(D9=0,0,E9/ABS(D9)) -> -0.0029821074 | G9: =SUM(G6:G8) -> 44600000 | H9: =IF(G9=0,0,(C9-G9)/ABS(G9)) -> 0.12443946 | I9: =IF(AND(ABS(E9)>=Inputs!$C$10,ABS(F9)>=Inputs!$C$11),"Explain","")
A10: 5000 | B10: =INDEX(CoA!$B$6:$B$46,MATCH($A10,CoA!$A$6:$A$46,0)) -> Cost of goods sold | C10: =INDEX(TB!$G$6:$G$46,MATCH($A10,TB!$A$6:$A$46,0)) -> 19600000 | D10: =INDEX(TB!$H$6:$H$46,MATCH($A10,TB!$A$6:$A$46,0)) -> 19300000 | E10: =D10-C10 -> -300000 | F10: =IF(D10=0,0,E10/ABS(D10)) -> -0.015544041 | G10: =INDEX(TB!$I$6:$I$46,MATCH($A10,TB!$A$6:$A$46,0)) -> 18200000 | H10: =IF(G10=0,0,(G10-C10)/ABS(G10)) -> -0.076923077 | I10: =IF(AND(ABS(E10)>=Inputs!$C$10,ABS(F10)>=Inputs!$C$11),"Explain","")
A11: 5010 | B11: =INDEX(CoA!$B$6:$B$46,MATCH($A11,CoA!$A$6:$A$46,0)) -> Freight inwards | C11: =INDEX(TB!$G$6:$G$46,MATCH($A11,TB!$A$6:$A$46,0)) -> 1700000 | D11: =INDEX(TB!$H$6:$H$46,MATCH($A11,TB!$A$6:$A$46,0)) -> 1600000 | E11: =D11-C11 -> -100000 | F11: =IF(D11=0,0,E11/ABS(D11)) -> -0.0625 | G11: =INDEX(TB!$I$6:$I$46,MATCH($A11,TB!$A$6:$A$46,0)) -> 1450000 | H11: =IF(G11=0,0,(G11-C11)/ABS(G11)) -> -0.17241379 | I11: =IF(AND(ABS(E11)>=Inputs!$C$10,ABS(F11)>=Inputs!$C$11),"Explain","") -> Explain | J11: DRAFT. Freight inwards $0.10m (6%) over budget; 3.4% of net sales vs 3.2% budget. Likely inbound container rates and online parcel mix. Confirm with Supply Chain whether the rate is a one-off or run-rate before the forecast refresh.
A12: 5020 | B12: =INDEX(CoA!$B$6:$B$46,MATCH($A12,CoA!$A$6:$A$46,0)) -> Inventory shrinkage and provisions | C12: =INDEX(TB!$G$6:$G$46,MATCH($A12,TB!$A$6:$A$46,0)) -> 420000 | D12: =INDEX(TB!$H$6:$H$46,MATCH($A12,TB!$A$6:$A$46,0)) -> 350000 | E12: =D12-C12 -> -70000 | F12: =IF(D12=0,0,E12/ABS(D12)) -> -0.2 | G12: =INDEX(TB!$I$6:$I$46,MATCH($A12,TB!$A$6:$A$46,0)) -> 330000 | H12: =IF(G12=0,0,(G12-C12)/ABS(G12)) -> -0.27272727 | I12: =IF(AND(ABS(E12)>=Inputs!$C$10,ABS(F12)>=Inputs!$C$11),"Explain","") | J12: DRAFT. Shrinkage $70k over budget, below the explain threshold. Q1 cycle count variance of $265k (INV-01) is not yet posted; once journalled shrinkage becomes about $685k vs $350k budget and will need explanation. Supply Chain Finance to confirm store split.
B13: Total cost of goods sold | C13: =SUM(C10:C12) -> 21720000 | D13: =SUM(D10:D12) -> 21250000 | E13: =D13-C13 -> -470000 | F13: =IF(D13=0,0,E13/ABS(D13)) -> -0.022117647 | G13: =SUM(G10:G12) -> 19980000 | H13: =IF(G13=0,0,(G13-C13)/ABS(G13)) -> -0.087087087 | I13: =IF(AND(ABS(E13)>=Inputs!$C$10,ABS(F13)>=Inputs!$C$11),"Explain","")
B14: Gross profit | C14: =C9-C13 -> 28430000 | D14: =D9-D13 -> 29050000 | E14: =C14-D14 -> -620000 | F14: =IF(D14=0,0,E14/ABS(D14)) -> -0.021342513 | G14: =G9-G13 -> 24620000 | H14: =IF(G14=0,0,(C14-G14)/ABS(G14)) -> 0.15475223 | I14: =IF(AND(ABS(E14)>=Inputs!$C$10,ABS(F14)>=Inputs!$C$11),"Explain","")
B15: Gross margin % | C15: =IF(C9=0,0,C14/C9) -> 0.5668993 | D15: =IF(D9=0,0,D14/D9) -> 0.57753479 | G15: =IF(G9=0,0,G14/G9) -> 0.55201794
